Workbook
Name ___________fl1111: {"Fecha_Novembro",#N/A,FALSE,"FECHAMENTO-2002 ";"Defer_Novembro",#N/A,FALSE,"DIFERIDO";"Pis_Novembro",#N/A,FALSE,"PIS COFINS";"Iss_Novembro",#N/A,FALSE,"ISS"}
Name __________fl1111: {"Fecha_Novembro",#N/A,FALSE,"FECHAMENTO-2002 ";"Defer_Novembro",#N/A,FALSE,"DIFERIDO";"Pis_Novembro",#N/A,FALSE,"PIS COFINS";"Iss_Novembro",#N/A,FALSE,"ISS"}
Name _________fl1111: {"Fecha_Novembro",#N/A,FALSE,"FECHAMENTO-2002 ";"Defer_Novembro",#N/A,FALSE,"DIFERIDO";"Pis_Novembro",#N/A,FALSE,"PIS COFINS";"Iss_Novembro",#N/A,FALSE,"ISS"}
Name ________fl1111: {"Fecha_Novembro",#N/A,FALSE,"FECHAMENTO-2002 ";"Defer_Novembro",#N/A,FALSE,"DIFERIDO";"Pis_Novembro",#N/A,FALSE,"PIS COFINS";"Iss_Novembro",#N/A,FALSE,"ISS"}
Name _______fl1111: {"Fecha_Novembro",#N/A,FALSE,"FECHAMENTO-2002 ";"Defer_Novembro",#N/A,FALSE,"DIFERIDO";"Pis_Novembro",#N/A,FALSE,"PIS COFINS";"Iss_Novembro",#N/A,FALSE,"ISS"}
Name ______fl1111: {"Fecha_Novembro",#N/A,FALSE,"FECHAMENTO-2002 ";"Defer_Novembro",#N/A,FALSE,"DIFERIDO";"Pis_Novembro",#N/A,FALSE,"PIS COFINS";"Iss_Novembro",#N/A,FALSE,"ISS"}
Name ____fl1111: {"Fecha_Novembro",#N/A,FALSE,"FECHAMENTO-2002 ";"Defer_Novembro",#N/A,FALSE,"DIFERIDO";"Pis_Novembro",#N/A,FALSE,"PIS COFINS";"Iss_Novembro",#N/A,FALSE,"ISS"}
Name ___dc1: {#N/A,#N/A,FALSE,"Aging Summary";#N/A,#N/A,FALSE,"Ratio Analysis";#N/A,#N/A,FALSE,"Test 120 Day Accts";#N/A,#N/A,FALSE,"Tickmarks"}
Name ___xlc_DefaultDisplayOption___: "caption"
Name ___xlc_DisplayNullValuesAs___: "___xlc_DisplayNullValuesAs_empty___"
Name ___xlc_PromptForInsertOnDrill___: FALSE
Name ___xlc_SuppressNULLSOnDrill___: TRUE
Name ___xlc_SuppressZerosOnDrill___: FALSE
Name __123Graph_AANIDRO: [1]PRODUCAO!$C$4:$F$4
Name __123Graph_AHIALCOOL: [1]PRODUCAO!$C$8:$F$8
Name __123Graph_AHIDRATADO: [1]PRODUCAO!$C$6:$F$6
Name __123Graph_AINDMES: [2]TESTE!$AG$74:$AP$74
Name __123Graph_AJAYME: '[3]RF-G7'!$AC$47:$AC$59
Name __123Graph_AMERC: [2]TESTE!$AR$4:$AR$26
Name __123Graph_ARESFIN: [2]TESTE!$V$131:$V$151
Name __123Graph_ASACAS: [1]PRODUCAO!$C$11:$F$11
Name __123Graph_ASIDECO: '[4]fluxo de caixa'!#REF!
Name __123Graph_AUSS: [2]TESTE!$H$132:$H$195
Name __123Graph_B: [5]ce!#REF!
Name __123Graph_BINDMES: [2]TESTE!$AG$75:$AP$75
Name __123Graph_BJAYME: '[3]RF-G7'!$AE$47:$AE$47
Name __123Graph_BMERC: [2]TESTE!$AY$4:$AY$26
Name __123Graph_BRESFIN: [2]TESTE!$W$131:$W$151
Name __123Graph_BSIDECO: '[4]fluxo de caixa'!#REF!
Name __123Graph_C: [2]TESTE!$AG$77:$AP$77
Name __123Graph_CINDMES: [2]TESTE!$AG$77:$AP$77
Name __123Graph_CJAYME: '[3]RF-G7'!$AD$47:$AD$59
Name __123Graph_CMERC: [2]TESTE!$BG$4:$BG$26
Name __123Graph_CRESFIN: [2]TESTE!$X$131:$X$152
Name __123Graph_CSIDECO: '[4]fluxo de caixa'!#REF!
Name __123Graph_D: '[6]Pag .11 À 13'!#REF!
Name __123Graph_DINDMES: [2]TESTE!$AG$79:$AP$79
Name __123Graph_F: '[3]RF-G7'!$AD$48:$AD$59
Name __123Graph_XANIDRO: [1]PRODUCAO!$C$3:$F$3
Name __123Graph_XHIALCOOL: [1]PRODUCAO!$C$3:$F$3
Name __123Graph_XHIDRATADO: [1]PRODUCAO!$C$3:$F$3
Name __123Graph_XINDMES: [2]TESTE!$AG$73:$AP$73
Name __123Graph_XJAYME: '[3]RF-G7'!$AB$47:$AB$59
Name __123Graph_XMERC: [2]TESTE!$AQ$4:$AQ$26
Name __123Graph_XRESFIN: [2]TESTE!$Q$131:$Q$152
Name __123Graph_XSACAS: [1]PRODUCAO!$C$3:$F$3
Name __123Graph_XSIDECO: '[4]fluxo de caixa'!#REF!
Name __123Graph_XUSS: [2]TESTE!$B$132:$B$195
Name __dc1: {#N/A,#N/A,FALSE,"Aging Summary";#N/A,#N/A,FALSE,"Ratio Analysis";#N/A,#N/A,FALSE,"Test 120 Day Accts";#N/A,#N/A,FALSE,"Tickmarks"}
Name __FDS_HYPERLINK_TOGGLE_STATE__: "ON"
Name __g4: {"VERGALHÃO",#N/A,FALSE,"DIÁRIA";"CATODO",#N/A,FALSE,"DIÁRIA"}
Name __IntlFixup: TRUE
Name __s2: '[7]sales vol.'!$J$398:$J$401
Name __s3: '[7]sales vol.'!$J$211:$J$214
Name __s4: '[7]sales vol.'!$I$1121:$I$1122
Name __s5: '[7]sales vol.'!$I$1632:$I$1635
Name __s6: '[7]sales vol.'!$I$2248:$I$2251
Name _1_0__123Grap: [8]ICATU!#REF!
Name _1_123Grap: [9]análise!#REF!
Name _12__123Graph_BCHART_1: '[10]#REF'!#REF!

Sheet Modelo
B7: Valores em R$ (Milhares) | C7: Unidade | D7: 1T17 | E7: 2T17 | F7: 3T17 | G7: 4T17 | H7: 1T18 | I7: 2T18 | J7: 3T18 | K7: 4T18 | L7: 1T19 | M7: 2T19 | N7: 3T19 | O7: 4T19 | P7: 1T20 | Q7: 2T20 | R7: 3T20 | S7: 4T20 | T7: 1T21 | U7: 2T21 | V7: 3T21 | W7: 4T21 | X7: 1T22 | Y7: 2T22 | Z7: 3T22 | AA7: 4T22 | AB7: 1T23 | AC7: 2T23 | AD7: 3T23 | AE7: 4T23 | AF7: 1T24 | AG7: 2T24 | AH7: 3T24 | AI7: 4T24 | AJ7: 1T25 | AK7: ='Build-Up'!AK7 -> 2T25 | AL7: ='Build-Up'!AL7 -> 3T25 | AM7: ='Build-Up'!AM7 -> 4T25 | AN7: ='Build-Up'!AN7 -> 1T26 | AO7: ='Build-Up'!AO7 -> 2T26 | AP7: ='Build-Up'!AP7 -> 3T26 | AQ7: ='Build-Up'!AQ7 -> 4T26 | AR7: ='Build-Up'!AR7 -> 1T27 | ... BW7: ='Build-Up'!BW7 -> 4T34 | BX7: x | BY7: ='Build-Up'!BY7 -> 2017 | BZ7: ='Build-Up'!BZ7 -> 2018 | CA7: ='Build-Up'!CA7 -> 2019 | CB7: ='Build-Up'!CB7 -> 2020 | CC7: ='Build-Up'!CC7 -> 2021 | CD7: ='Build-Up'!CD7 -> 2022 | CE7: ='Build-Up'!CE7 -> 2023 | CF7: ='Build-Up'!CF7 -> 2024 | ... CP7: ='Build-Up'!CP7 -> 2034 | CQ7: x
BX8: x | CQ8: x
A9: l | B9: DRE | BX9: x | CQ9: x
BX10: x | CQ10: x
B11: Receita Líquida | C11: [BRL 000] | D11: =Inputs!F141/1000 -> 52.292 | E11: =Inputs!G141/1000 -> 54.026 | F11: =Inputs!H141/1000 -> 61.399 | G11: =Inputs!I141/1000 -> 68.785 | H11: =Inputs!J141/1000 -> 76.096 | I11: =Inputs!K141/1000 -> 84.326 | J11: =Inputs!L141/1000 -> 79.884 | K11: =Inputs!M141/1000 -> 86.931 | ... AJ11: =Inputs!AL141/1000 -> 368.845 | AK11: ='Build-Up'!AK20 -> 354.5325 | AL11: ='Build-Up'!AL20 -> 359.18181 | AM11: ='Build-Up'!AM20 -> 409.38174 | AN11: ='Build-Up'!AN20 -> 384.94945 | AO11: ='Build-Up'!AO20 -> 385.23919 | AP11: ='Build-Up'!AP20 -> 402.18972 | AQ11: ='Build-Up'!AQ20 -> 455.09592 | AR11: ='Build-Up'!AR20 -> 425.82731 | ... BW11: ='Build-Up'!BW20 -> 924.48804 | BX11: x | BY11: =SUM(D11:G11) -> 236.502 | BZ11: =SUM(H11:K11) -> 327.237 | CA11: =SUM(L11:O11) -> 348.612 | CB11: =SUM(P11:S11) -> 242.213 | CC11: =SUM(T11:W11) -> 433.141 | CD11: =SUM(X11:AA11) -> 813.494 | CE11: =SUM(AB11:AE11) -> 1046.41 | CF11: =SUM(AF11:AI11) -> 1234.06 | CG11: =SUM(AJ11:AM11) -> 1491.9411 | CH11: =SUM(AN11:AQ11) -> 1627.4743 | CI11: =SUM(AR11:AU11) -> 1787.6551 | CJ11: =SUM(AV11:AY11) -> 1953.2532 | CK11: =SUM(AZ11:BC11) -> 2134.1912 | CL11: =SUM(BD11:BG11) -> 2331.8903 | CM11: =SUM(BH11:BK11) -> 2547.9032 | CN11: =SUM(BL11:BO11) -> 2783.9262 | CO11: =SUM(BP11:BS11) -> 3041.813 | CP11: =SUM(BT11:BW11) -> 3323.5889 | CQ11: x
B12: a/a % | H12: =H11/D11-1 -> 0.45521303 | I12: =I11/E11-1 -> 0.56084108 | J12: =J11/F11-1 -> 0.30106354 | K12: =K11/G11-1 -> 0.26380752 | L12: =L11/H11-1 -> 0.089150547 | M12: =M11/I11-1 -> 0.096411546 | N12: =N11/J11-1 -> 0.068899905 | O12: =O11/K11-1 -> 0.011008731 | ... BW12: =BW11/BS11-1 -> 0.09263421 | BX12: x | BZ12: =BZ11/BY11-1 -> 0.38365426 | CA12: =CA11/BZ11-1 -> 0.065319631 | CB12: =CB11/CA11-1 -> -0.30520751 | CC12: =CC11/CB11-1 -> 0.78826487 | CD12: =CD11/CC11-1 -> 0.87812745 | CE12: =CE11/CD11-1 -> 0.28631557 | CF12: =CF11/CE11-1 -> 0.17932741 | CG12: =CG11/CF11-1 -> 0.20896962 | ... CP12: =CP11/CO11-1 -> 0.09263421 | CQ12: x
BX13: x | CQ13: x
B14: COGS | C14: [BRL 000] | D14: =Inputs!F142/1000 -> -39.486 | E14: =Inputs!G142/1000 -> -44.543 | F14: =Inputs!H142/1000 -> -57.243 | G14: =Inputs!I142/1000 -> -61.827 | H14: =Inputs!J142/1000 -> -65.521 | I14: =Inputs!K142/1000 -> -77.319 | J14: =Inputs!L142/1000 -> -70.948 | K14: =Inputs!M142/1000 -> -68.426 | ... AJ14: =Inputs!AL142/1000 -> -295.005 | AK14: ='Build-Up'!AK50 -> -279.49002 | AL14: ='Build-Up'!AL50 -> -280.44507 | AM14: ='Build-Up'!AM50 -> -321.04799 | AN14: ='Build-Up'!AN50 -> -302.16683 | AO14: ='Build-Up'!AO50 -> -302.54252 | AP14: ='Build-Up'!AP50 -> -312.84841 | AQ14: ='Build-Up'!AQ50 -> -355.33199 | AR14: ='Build-Up'!AR50 -> -333.26288 | ... BW14: ='Build-Up'!BW50 -> -720.599 | BX14: x | BY14: =SUM(D14:G14) -> -203.099 | BZ14: =SUM(H14:K14) -> -282.214 | CA14: =SUM(L14:O14) -> -299.585 | CB14: =SUM(P14:S14) -> -215.064 | CC14: =SUM(T14:W14) -> -362.687 | CD14: =SUM(X14:AA14) -> -614.912 | CE14: =SUM(AB14:AE14) -> -830.84 | CF14: =SUM(AF14:AI14) -> -960.465 | CG14: =SUM(AJ14:AM14) -> -1175.9881 | CH14: =SUM(AN14:AQ14) -> -1272.8898 | CI14: =SUM(AR14:AU14) -> -1394.9603 | CJ14: =SUM(AV14:AY14) -> -1524.1814 | CK14: =SUM(AZ14:BC14) -> -1665.3727 | CL14: =SUM(BD14:BG14) -> -1819.6432 | CM14: =SUM(BH14:BK14) -> -1988.2044 | CN14: =SUM(BL14:BO14) -> -2172.3802 | CO14: =SUM(BP14:BS14) -> -2373.6169 | CP14: =SUM(BT14:BW14) -> -2593.495 | CQ14: x
B15: a/a % | C15: [%] | H15: =H14/D14-1 -> 0.65934762 | I15: =I14/E14-1 -> 0.7358283 | J15: =J14/F14-1 -> 0.23941792 | K15: =K14/G14-1 -> 0.1067333 | L15: =L14/H14-1 -> 0.10422613 | M15: =M14/I14-1 -> 0.031686907 | N15: =N14/J14-1 -> 0.052122681 | O15: =O14/K14-1 -> 0.064215357 | ... BW15: =BW14/BS14-1 -> 0.09263421 | BX15: x | BZ15: =BZ14/BY14-1 -> 0.38953909 | CA15: =CA14/BZ14-1 -> 0.061552581 | CB15: =CB14/CA14-1 -> -0.28212694 | CC15: =CC14/CB14-1 -> 0.68641428 | CD15: =CD14/CC14-1 -> 0.69543436 | CE15: =CE14/CD14-1 -> 0.35115269 | CF15: =CF14/CE14-1 -> 0.1560168 | CG15: =CG14/CF14-1 -> 0.22439451 | ... CP15: =CP14/CO14-1 -> 0.09263421 | CQ15: x
BX16: x | CQ16: x
B17: Lucro Bruto | C17: [BRL 000] | D17: =Inputs!F144/1000 -> 12.806 | E17: =Inputs!G144/1000 -> 9.483 | F17: =Inputs!H144/1000 -> 4.156 | G17: =Inputs!I144/1000 -> 6.958 | H17: =Inputs!J144/1000 -> 10.575 | I17: =Inputs!K144/1000 -> 7.007 | J17: =Inputs!L144/1000 -> 8.936 | K17: =Inputs!M144/1000 -> 18.505 | ... AJ17: =Inputs!AL144/1000 -> 73.84 | AK17: =AK11+AK14 -> 75.042484 | AL17: =AL11+AL14 -> 78.736739 | AM17: =AM11+AM14 -> 88.333756 | AN17: =AN11+AN14 -> 82.782618 | AO17: =AO11+AO14 -> 82.696673 | AP17: =AP11+AP14 -> 89.341308 | AQ17: =AQ11+AQ14 -> 99.76393 | AR17: =AR11+AR14 -> 92.564426 | ... BW17: =BW11+BW14 -> 203.88904 | BX17: x | BY17: =SUM(D17:G17) -> 33.403 | BZ17: =SUM(H17:K17) -> 45.023 | CA17: =SUM(L17:O17) -> 49.027 | CB17: =SUM(P17:S17) -> 27.149 | CC17: =SUM(T17:W17) -> 70.454 | CD17: =SUM(X17:AA17) -> 198.582 | CE17: =SUM(AB17:AE17) -> 215.57 | CF17: =SUM(AF17:AI17) -> 273.595 | CG17: =SUM(AJ17:AM17) -> 315.95298 | CH17: =SUM(AN17:AQ17) -> 354.58453 | CI17: =SUM(AR17:AU17) -> 392.69481 | CJ17: =SUM(AV17:AY17) -> 429.07179 | CK17: =SUM(AZ17:BC17) -> 468.81852 | CL17: =SUM(BD17:BG17) -> 512.24715 | CM17: =SUM(BH17:BK17) -> 559.69876 | CN17: =SUM(BL17:BO17) -> 611.54601 | CO17: =SUM(BP17:BS17) -> 668.19609 | CP17: =SUM(BT17:BW17) -> 730.09391 | CQ17: x
B18: a/a % | C18: [%] | H18: =H17/D17-1 -> -0.17421521 | I18: =I17/E17-1 -> -0.26109881 | J18: =J17/F17-1 -> 1.1501444 | K18: =K17/G17-1 -> 1.6595286 | L18: =L17/H17-1 -> -0.0042553191 | M18: =M17/I17-1 -> 0.81061795 | N18: =N17/J17-1 -> 0.20210385 | O18: =O17/K17-1 -> -0.18573359 | ... BW18: =BW17/BS17-1 -> 0.09263421 | BX18: x | BZ18: =BZ17/BY17-1 -> 0.34787295 | CA18: =CA17/BZ17-1 -> 0.088932323 | CB18: =CB17/CA17-1 -> -0.44624391 | CC18: =CC17/CB17-1 -> 1.5950864 | CD18: =CD17/CC17-1 -> 1.818605 | CE18: =CE17/CD17-1 -> 0.085546525 | CF18: =CF17/CE17-1 -> 0.26917011 | CG18: =CG17/CF17-1 -> 0.15482 | ... CP18: =CP17/CO17-1 -> 0.09263421 | CQ18: x
B19: Margem Bruta | C19: [%] | D19: =D17/D11 -> 0.24489406 | E19: =E17/E11 -> 0.1755266 | F19: =F17/F11 -> 0.067688399 | G19: =G17/G11 -> 0.10115578 | H19: =H17/H11 -> 0.1389692 | I19: =I17/I11 -> 0.083094182 | J19: =J17/J11 -> 0.1118622 | K19: =K17/K11 -> 0.21286998 | ... BW19: =BW17/BW11 -> 0.22054265 | BX19: x | BY19: =BY17/BY11 -> 0.14123771 | BZ19: =BZ17/BZ11 -> 0.1375853 | CA19: =CA17/CA11 -> 0.14063486 | CB19: =CB17/CB11 -> 0.1120873 | CC19: =CC17/CC11 -> 0.16265835 | CD19: =CD17/CD11 -> 0.24410998 | CE19: =CE17/CE11 -> 0.20600912 | CF19: =CF17/CF11 -> 0.22170316 | ... CP19: =CP17/CP11 -> 0.21967034 | CQ19: x
BX20: x | CQ20: x
B21: SG&A | C21: [BRL 000] | D21: =Inputs!F147/1000 -> -9.014 | E21: =Inputs!G147/1000 -> -10.452 | F21: =Inputs!H147/1000 -> -8.349 | G21: =Inputs!I147/1000 -> -13.301 | H21: =Inputs!J147/1000 -> -8.349 | I21: =Inputs!K147/1000 -> -4.123 | J21: =Inputs!L147/1000 -> -5.844 | K21: =Inputs!M147/1000 -> -12.059 | ... AJ21: =Inputs!AL147/1000 -> -52.195 | AK21: ='Build-Up'!AK100 -> -50.883909 | AL21: ='Build-Up'!AL100 -> -40.035246 | AM21: ='Build-Up'!AM100 -> -52.137101 | AN21: ='Build-Up'!AN100 -> -42.344439 | AO21: ='Build-Up'!AO100 -> -42.376311 | AP21: ='Build-Up'!AP100 -> -44.240869 | AQ21: ='Build-Up'!AQ100 -> -50.060552 | AR21: ='Build-Up'!AR100 -> -44.711867 | ... BW21: ='Build-Up'!BW100 -> -92.448804 | BX21: x | BY21: =SUM(D21:G21) -> -41.116 | BZ21: =SUM(H21:K21) -> -30.375 | CA21: =SUM(L21:O21) -> -42.064 | CB21: =SUM(P21:S21) -> -31.998 | CC21: =SUM(T21:W21) -> -49.962 | CD21: =SUM(X21:AA21) -> -94.124 | CE21: =SUM(AB21:AE21) -> -128.172 | CF21: =SUM(AF21:AI21) -> -162.113 | CG21: =SUM(AJ21:AM21) -> -195.25126 | CH21: =SUM(AN21:AQ21) -> -179.02217 | CI21: =SUM(AR21:AU21) -> -187.70379 | CJ21: =SUM(AV21:AY21) -> -195.32532 | CK21: =SUM(AZ21:BC21) -> -213.41912 | CL21: =SUM(BD21:BG21) -> -233.18903 | CM21: =SUM(BH21:BK21) -> -254.79032 | CN21: =SUM(BL21:BO21) -> -278.39262 | CO21: =SUM(BP21:BS21) -> -304.1813 | CP21: =SUM(BT21:BW21) -> -332.35889 | CQ21: x
B22: a/a % | C22: [%] | H22: =H21/D21-1 -> -0.073774129 | I22: =I21/E21-1 -> -0.60553004 | J22: =J21/F21-1 -> -0.30003593 | K22: =K21/G21-1 -> -0.093376438 | L22: =L21/H21-1 -> 0.13067433 | M22: =M21/I21-1 -> 1.643706 | N22: =N21/J21-1 -> 0.92060233 | O22: =O21/K21-1 -> -0.12928103 | ... BW22: =BW21/BS21-1 -> 0.09263421 | BX22: x | BZ22: =BZ21/BY21-1 -> -0.2612365 | CA22: =CA21/BZ21-1 -> 0.38482305 | CB22: =CB21/CA21-1 -> -0.23930202 | CC22: =CC21/CB21-1 -> 0.56141009 | CD22: =CD21/CC21-1 -> 0.88391177 | CE22: =CE21/CD21-1 -> 0.36173558 | CF22: =CF21/CE21-1 -> 0.26480823 | CG22: =CG21/CF21-1 -> 0.20441455 | ... CP22: =CP21/CO21-1 -> 0.09263421 | CQ22: x
B23: SG&A ex D&A | C23: [BRL 000] | BX23: x | CQ23: x
B24: Como % da Receita Líquida | D24: =D21/D$11 -> -0.17237818 | E24: =E21/E$11 -> -0.19346241 | F24: =F21/F$11 -> -0.13597941 | G24: =G21/G$11 -> -0.19337065 | H24: =H21/H$11 -> -0.10971667 | I24: =I21/I$11 -> -0.04889358 | J24: =J21/J$11 -> -0.073156076 | K24: =K21/K$11 -> -0.13871921 | ... BW24: =BW21/BW$11 -> -0.1 | BX24: x | BY24: =BY21/BY$11 -> -0.17385054 | BZ24: =BZ21/BZ$11 -> -0.092822633 | CA24: =CA21/CA$11 -> -0.12066137 | CB24: =CB21/CB$11 -> -0.13210686 | CC24: =CC21/CC$11 -> -0.11534812 | CD24: =CD21/CD$11 -> -0.11570337 | CE24: =CE21/CE$11 -> -0.12248736 | CF24: =CF21/CF$11 -> -0.13136557 | ... CP24: =CP21/CP$11 -> -0.1 | CQ24: x
BX25: x | CQ25: x
B26: Equivalência Patrimonial | C26: [BRL 000] | D26: =Inputs!F149/1000 -> 0.174 | E26: =Inputs!G149/1000 -> 0.061 | F26: =Inputs!H149/1000 -> 0.212 | G26: =Inputs!I149/1000 -> -0.261 | H26: =Inputs!J149/1000 -> 0.607 | I26: =Inputs!K149/1000 -> 0.438 | J26: =Inputs!L149/1000 -> 0.116 | K26: =Inputs!M149/1000 -> -0.713 | ... AJ26: =Inputs!AL149/1000 -> 0 | AK26: =0 -> 0 | AL26: =0 -> 0 | AM26: =0 -> 0 | AN26: =0 -> 0 | AO26: =0 -> 0 | AP26: =0 -> 0 | AQ26: =0 -> 0 | AR26: =0 -> 0 | ... BW26: =0 -> 0 | BX26: x | BY26: =SUM(D26:G26) -> 0.186 | BZ26: =SUM(H26:K26) -> 0.448 | CA26: =SUM(L26:O26) -> 0.797 | CB26: =SUM(P26:S26) -> 0.217 | CC26: =SUM(T26:W26) -> 0 | CD26: =SUM(X26:AA26) -> 0 | CE26: =SUM(AB26:AE26) -> 0 | CF26: =SUM(AF26:AI26) -> 0 | CG26: =SUM(AJ26:AM26) -> 0 | CH26: =SUM(AN26:AQ26) -> 0 | CI26: =SUM(AR26:AU26) -> 0 | CJ26: =SUM(AV26:AY26) -> 0 | CK26: =SUM(AQ26:AT26) -> 0 | CL26: =SUM(AU26:AX26) -> 0 | CM26: =SUM(AY26:BB26) -> 0 | CN26: =SUM(AT26:AW26) -> 0 | CO26: =SUM(AX26:BA26) -> 0 | CP26: =SUM(BB26:BE26) -> 0 | CQ26: x
B27: a/a % | C27: [%] | BX27: x | BZ27: =BZ26/BY26-1 -> 1.4086022 | CA27: =CA26/BZ26-1 -> 0.77901786 | CB27: =CB26/CA26-1 -> -0.72772898 | CC27: =CC26/CB26-1 -> -1 | CQ27: x
BX28: x | CQ28: x
B29: EBIT | C29: [BRL 000] | D29: =Inputs!F151/1000 -> 3.966 | E29: =Inputs!G151/1000 -> -0.908 | F29: =Inputs!H151/1000 -> -3.981 | G29: =Inputs!I151/1000 -> -6.604 | H29: =Inputs!J151/1000 -> 2.833 | I29: =Inputs!K151/1000 -> 3.322 | J29: =Inputs!L151/1000 -> 3.208 | K29: =Inputs!M151/1000 -> 5.733 | ... AJ29: =Inputs!AL151/1000 -> 21.645 | AK29: =AK17+AK21+AK26 -> 24.158576 | AL29: =AL17+AL21+AL26 -> 38.701493 | AM29: =AM17+AM21+AM26 -> 36.196654 | AN29: =AN17+AN21+AN26 -> 40.438179 | AO29: =AO17+AO21+AO26 -> 40.320362 | AP29: =AP17+AP21+AP26 -> 45.10044 | AQ29: =AQ17+AQ21+AQ26 -> 49.703378 | AR29: =AR17+AR21+AR26 -> 47.852559 | ... BW29: =BW17+BW21+BW26 -> 111.44024 | BX29: x | BY29: =SUM(D29:G29) -> -7.527 | BZ29: =SUM(H29:K29) -> 15.096 | CA29: =SUM(L29:O29) -> 7.76 | CB29: =SUM(P29:S29) -> -4.632 | CC29: =SUM(T29:W29) -> 20.492 | CD29: =SUM(X29:AA29) -> 104.458 | CE29: =SUM(AB29:AE29) -> 87.398 | CF29: =SUM(AF29:AI29) -> 111.482 | CG29: =SUM(AJ29:AM29) -> 120.70172 | CH29: =SUM(AN29:AQ29) -> 175.56236 | CI29: =SUM(AR29:AU29) -> 204.99103 | CJ29: =SUM(AV29:AY29) -> 233.74647 | CK29: =SUM(AZ29:BC29) -> 255.39939 | CL29: =SUM(BD29:BG29) -> 279.05811 | CM29: =SUM(BH29:BK29) -> 304.90844 | CN29: =SUM(BL29:BO29) -> 333.15339 | CO29: =SUM(BP29:BS29) -> 364.0148 | CP29: =SUM(BT29:BW29) -> 397.73502 | CQ29: x
B30: a/a % | C30: [%] | H30: =H29/D29-1 -> -0.28567827 | I30: =I29/E29-1 -> -4.6585903 | J30: =J29/F29-1 -> -1.8058277 | K30: =K29/G29-1 -> -1.8681102 | L30: =L29/H29-1 -> -0.67278503 | M30: =M29/I29-1 -> -0.37537628 | N30: =N29/J29-1 -> -1.2300499 | O30: =O29/K29-1 -> -0.041339613 | ... BW30: =BW29/BS29-1 -> 0.09263421 | BX30: x | BZ30: =BZ29/BY29-1 -> -3.0055799 | CA30: =CA29/BZ29-1 -> -0.48595654 | CB30: =CB29/CA29-1 -> -1.5969072 | CC30: =CC29/CB29-1 -> -5.4240069 | CD30: =CD29/CC29-1 -> 4.0975015 | CE30: =CE29/CD29-1 -> -0.16331923 | CF30: =CF29/CE29-1 -> 0.27556695 | CG30: =CG29/CF29-1 -> 0.082701451 | ... CP30: =CP29/CO29-1 -> 0.09263421 | CQ30: x
B31: Margem Operacional | C31: [%] | D31: =D29/D$11 -> 0.075843341 | E31: =E29/E$11 -> -0.016806723 | F31: =F29/F$11 -> -0.06483819 | G31: =G29/G$11 -> -0.096009304 | H31: =H29/H$11 -> 0.037229289 | I31: =I29/I$11 -> 0.03939473 | J31: =J29/J$11 -> 0.040158229 | K31: =K29/K$11 -> 0.065948856 | ... BW31: =BW29/BW$11 -> 0.12054265 | BX31: x | BY31: =BY29/BY$11 -> -0.031826369 | BZ31: =BZ29/BZ$11 -> 0.046131703 | CA31: =CA29/CA$11 -> 0.022259704 | CB31: =CB29/CB$11 -> -0.019123664 | CC31: =CC29/CC$11 -> 0.047310229 | CD31: =CD29/CD$11 -> 0.1284066 | CE31: =CE29/CE$11 -> 0.083521755 | CF31: =CF29/CF$11 -> 0.090337585 | ... CP31: =CP29/CP$11 -> 0.11967034 | CQ31: x
BX32: x | CQ32: x
B33: Financial Result | C33: [BRL 000] | D33: =+D35+D36 -> -0.868 | E33: =+E35+E36 -> -1.397 | F33: =+F35+F36 -> -2.506 | G33: =+G35+G36 -> -1.364 | H33: =+H35+H36 -> -2.428 | I33: =+I35+I36 -> -2.741 | J33: =+J35+J36 -> -2.071 | K33: =+K35+K36 -> -1.891 | ... BW33: =+BW35+BW36 -> 6.1974863 | BX33: x | BY33: =SUM(D33:G33) -> -6.135 | BZ33: =SUM(H33:K33) -> -9.131 | CA33: =SUM(L33:O33) -> -13.585 | CB33: =SUM(P33:S33) -> -6.51 | CC33: =SUM(T33:W33) -> -4.313 | CD33: =SUM(X33:AA33) -> -20.278 | CE33: =SUM(AB33:AE33) -> -44.988 | CF33: =SUM(AF33:AI33) -> -52.08 | CG33: =SUM(AJ33:AM33) -> -61.170767 | CH33: =SUM(AN33:AQ33) -> -50.055028 | CI33: =SUM(AR33:AU33) -> -40.96294 | CJ33: =SUM(AV33:AY33) -> -30.595345 | CK33: =SUM(AZ33:BC33) -> -23.681527 | CL33: =SUM(BD33:BG33) -> -17.804875 | CM33: =SUM(BH33:BK33) -> -11.205348 | CN33: =SUM(BL33:BO33) -> -3.7770395 | CO33: =SUM(BP33:BS33) -> 5.1320396 | CP33: =SUM(BT33:BW33) -> 17.300264 | CQ33: x
B34: a/a % | C34: [%] | H34: =H33/D33-1 -> 1.797235 | I34: =I33/E33-1 -> 0.96206156 | J34: =J33/F33-1 -> -0.1735834 | K34: =K33/G33-1 -> 0.38636364 | L34: =L33/H33-1 -> 0.030889621 | M34: =M33/I33-1 -> 0.44582269 | N34: =N33/J33-1 -> 0.76388218 | O34: =O33/K33-1 -> 0.83289265 | ... BW34: =BW33/BS33-1 -> 1.1063754 | BX34: x | BZ34: =BZ33/BY33-1 -> 0.48834556 | CA34: =CA33/BZ33-1 -> 0.48778885 | CB34: =CB33/CA33-1 -> -0.52079499 | CC34: =CC33/CB33-1 -> -0.3374808 | CD34: =CD33/CC33-1 -> 3.7015998 | CE34: =CE33/CD33-1 -> 1.218562 | CF34: =CF33/CE33-1 -> 0.15764204 | CG34: =CG33/CF33-1 -> 0.1745539 | ... CP34: =CP33/CO33-1 -> 2.3710309 | CQ34: x
B35: Receita Financeira | C35: [BRL 000] | D35: =Inputs!F154/1000 -> 0.544 | E35: =Inputs!G154/1000 -> 0.555 | F35: =Inputs!H154/1000 -> 0.776 | G35: =Inputs!I154/1000 -> 0.508 | H35: =Inputs!J154/1000 -> 0.895 | I35: =Inputs!K154/1000 -> 1.644 | J35: =Inputs!L154/1000 -> 2.601 | K35: =Inputs!M154/1000 -> 1.191 | ... AJ35: =Inputs!AL154/1000 -> 7.978 | AK35: =AK243 -> 7.978 | AL35: =AL243 -> 13.517288 | AM35: =AM243 -> 16.641643 | AN35: =AN243 -> 17.492021 | AO35: =AO243 -> 14.104637 | AP35: =AP243 -> 11.345184 | AQ35: =AQ243 -> 14.303383 | AR35: =AR243 -> 15.374316 | ... BW35: =BW243 -> 25.942027 | BX35: x | BY35: =SUM(D35:G35) -> 2.383 | BZ35: =SUM(H35:K35) -> 6.331 | CA35: =SUM(L35:O35) -> 4.465 | CB35: =SUM(P35:S35) -> 4.9 | CC35: =SUM(T35:W35) -> 4.211 | CD35: =SUM(X35:AA35) -> 9.765 | CE35: =SUM(AB35:AE35) -> 14.043 | CF35: =SUM(AF35:AI35) -> 23.376 | CG35: =SUM(AJ35:AM35) -> 46.114931 | CH35: =SUM(AN35:AQ35) -> 57.245224 | CI35: =SUM(AR35:AU35) -> 50.962464 | CJ35: =SUM(AV35:AY35) -> 50.810426 | CK35: =SUM(AZ35:BC35) -> 55.296637 | CL35: =SUM(BD35:BG35) -> 61.173289 | CM35: =SUM(BH35:BK35) -> 67.772816 | CN35: =SUM(BL35:BO35) -> 75.201125 | CO35: =SUM(BP35:BS35) -> 84.110204 | CP35: =SUM(BT35:BW35) -> 96.278428 | CQ35: x
B36: Despesa Financeira | C36: [BRL 000] | D36: =Inputs!F155/1000 -> -1.412 | E36: =Inputs!G155/1000 -> -1.952 | F36: =Inputs!H155/1000 -> -3.282 | G36: =Inputs!I155/1000 -> -1.872 | H36: =Inputs!J155/1000 -> -3.323 | I36: =Inputs!K155/1000 -> -4.385 | J36: =Inputs!L155/1000 -> -4.672 | K36: =Inputs!M155/1000 -> -3.082 | ... AJ36: =Inputs!AL155/1000 -> -23.776 | AK36: =AK240 -> -27.836566 | AL36: =AL240 -> -27.836566 | AM36: =AM240 -> -27.836566 | AN36: =AN240 -> -27.836566 | AO36: =AO240 -> -27.836566 | AP36: =AP240 -> -27.836566 | AQ36: =AQ240 -> -23.790554 | AR36: =AR240 -> -23.790554 | ... BW36: =BW240 -> -19.744541 | BX36: x | BY36: =SUM(D36:G36) -> -8.518 | BZ36: =SUM(H36:K36) -> -15.462 | CA36: =SUM(L36:O36) -> -18.05 | CB36: =SUM(P36:S36) -> -11.41 | CC36: =SUM(T36:W36) -> -8.524 | CD36: =SUM(X36:AA36) -> -30.043 | CE36: =SUM(AB36:AE36) -> -59.031 | CF36: =SUM(AF36:AI36) -> -75.456 | CG36: =SUM(AJ36:AM36) -> -107.2857 | CH36: =SUM(AN36:AQ36) -> -107.30025 | CI36: =SUM(AR36:AU36) -> -91.925404 | CJ36: =SUM(AV36:AY36) -> -81.405772 | CK36: =SUM(AZ36:BC36) -> -78.978164 | CL36: =SUM(BD36:BG36) -> -78.978164 | CM36: =SUM(BH36:BK36) -> -78.978164 | CN36: =SUM(BL36:BO36) -> -78.978164 | CO36: =SUM(BP36:BS36) -> -78.978164 | CP36: =SUM(BT36:BW36) -> -78.978164 | CQ36: x
BX37: x | CQ37: x | CV37: 264 | CW37: 400 | CX37: =(CW37/CV37)^(1/2)-1 -> 0.23091491
B38: EBT | C38: [BRL 000] | D38: =Inputs!F157/1000 -> 3.098 | E38: =Inputs!G157/1000 -> -2.305 | F38: =Inputs!H157/1000 -> -6.487 | G38: =Inputs!I157/1000 -> -7.968 | H38: =Inputs!J157/1000 -> 0.405 | I38: =Inputs!K157/1000 -> 0.581 | J38: =Inputs!L157/1000 -> 1.137 | K38: =Inputs!M157/1000 -> 3.842 | ... AJ38: =Inputs!AL157/1000 -> 5.847 | AK38: =AK29+AK33 -> 4.3000098 | AL38: =AL29+AL33 -> 24.382215 | AM38: =AM29+AM33 -> 25.001731 | AN38: =AN29+AN33 -> 30.093633 | AO38: =AO29+AO33 -> 26.588433 | AP38: =AP29+AP33 -> 28.609057 | AQ38: =AQ29+AQ33 -> 40.216208 | AR38: =AR29+AR33 -> 39.436321 | ... BW38: =BW29+BW33 -> 117.63773 | BX38: x | BY38: =SUM(D38:G38) -> -13.662 | BZ38: =SUM(H38:K38) -> 5.965 | CA38: =SUM(L38:O38) -> -5.825 | CB38: =SUM(P38:S38) -> -11.142 | CC38: =SUM(T38:W38) -> 16.179 | CD38: =SUM(X38:AA38) -> 84.18 | CE38: =SUM(AB38:AE38) -> 42.41 | CF38: =SUM(AF38:AI38) -> 59.402 | CG38: =SUM(AJ38:AM38) -> 59.530956 | CH38: =SUM(AN38:AQ38) -> 125.50733 | CI38: =SUM(AR38:AU38) -> 164.02809 | CJ38: =SUM(AV38:AY38) -> 203.15113 | CK38: =SUM(AZ38:BC38) -> 231.71787 | CL38: =SUM(BD38:BG38) -> 261.25324 | CM38: =SUM(BH38:BK38) -> 293.70309 | CN38: =SUM(BL38:BO38) -> 329.37635 | CO38: =SUM(BP38:BS38) -> 369.14684 | CP38: =SUM(BT38:BW38) -> 415.03528 | CQ38: x
B39: a/a % | C39: [%] | H39: =H38/D38-1 -> -0.8692705 | I39: =I38/E38-1 -> -1.2520607 | J39: =J38/F38-1 -> -1.1752736 | K39: =K38/G38-1 -> -1.4821787 | L39: =L38/H38-1 -> -4.891358 | M39: =M38/I38-1 -> -4.2495697 | N39: =N38/J38-1 -> -4.8619173 | O39: =O38/K38-1 -> -0.47162936 | ... BW39: =BW38/BS38-1 -> 0.12105843 | BX39: x | CQ39: x
B40: Margem EBT | C40: [%] | D40: =D38/D$11 -> 0.059244244 | E40: =E38/E$11 -> -0.042664643 | F40: =F38/F$11 -> -0.10565319 | G40: =G38/G$11 -> -0.11583921 | H40: =H38/H$11 -> 0.0053222246 | I40: =I38/I$11 -> 0.0068899272 | J40: =J38/J$11 -> 0.014233138 | K40: =K38/K$11 -> 0.044195972 | ... BW40: =BW38/BW$11 -> 0.12724635 | BX40: x | BZ40: =BZ38/BZ$11 -> 0.018228379 | CA40: =CA38/CA$11 -> -0.016709121 | CB40: =CB38/CB$11 -> -0.046000834 | CC40: =CC38/CC$11 -> 0.037352733 | CD40: =CD38/CD$11 -> 0.10347956 | CE40: =CE38/CE$11 -> 0.040529047 | CF40: =CF38/CF$11 -> 0.048135423 | CG40: =CG38/CG$11 -> 0.039901681 | ... CP40: =CP38/CP$11 -> 0.12487564 | CQ40: x
BX41: x | CQ41: x
B42: IR | C42: [BRL 000] | D42: =(Inputs!F159/1000)+(Inputs!F160/1000) -> -0.826 | E42: =(Inputs!G159/1000)+(Inputs!G160/1000) -> 0.952 | F42: =(Inputs!H159/1000)+(Inputs!H160/1000) -> 2.424 | G42: =(Inputs!I159/1000)+(Inputs!I160/1000) -> 3.724 | H42: =(Inputs!J159/1000)+(Inputs!J160/1000) -> 0.315 | I42: =(Inputs!K159/1000)+(Inputs!K160/1000) -> -0.423 | J42: =(Inputs!L159/1000)+(Inputs!L160/1000) -> -2.329 | K42: =(Inputs!M159/1000)+(Inputs!M160/1000) -> 1.612 | ... AJ42: =(Inputs!AL159/1000)+(Inputs!AL160/1000) -> -1.83 | AK42: =-AK38*AK43 -> -1.3458214 | AL42: =-AL38*AL43 -> -7.6311703 | AM42: =-AM38*AM43 -> -7.8250673 | AN42: =-AN38*AN43 -> -9.4187359 | AO42: =-AO38*AO43 -> -8.3216747 | AP42: =-AP38*AP43 -> -8.9540918 | AQ42: =-AQ38*AQ43 -> -12.58691 | AR42: =-AR38*AR43 -> -12.34282 | ... BW42: =-BW38*BW43 -> -36.818375 | BX42: x | BY42: =SUM(D42:G42) -> 6.274 | BZ42: =SUM(H42:K42) -> -0.825 | CA42: =SUM(L42:O42) -> -4.973 | CB42: =SUM(P42:S42) -> 8.046 | CC42: =SUM(T42:W42) -> -1.68 | CD42: =SUM(X42:AA42) -> -19.246 | CE42: =SUM(AB42:AE42) -> -17.331 | CF42: =SUM(AF42:AI42) -> -17.147 | CG42: =SUM(AJ42:AM42) -> -18.632059 | CH42: =SUM(AN42:AQ42) -> -39.281412 | CI42: =SUM(AR42:AU42) -> -51.337677 | CJ42: =SUM(AV42:AY42) -> -63.582446 | CK42: =SUM(AZ42:BC42) -> -72.523293 | CL42: =SUM(BD42:BG42) -> -81.767304 | CM42: =SUM(BH42:BK42) -> -91.923493 | CN42: =SUM(BL42:BO42) -> -103.08855 | CO42: =SUM(BP42:BS42) -> -115.53595 | CP42: =SUM(BT42:BW42) -> -129.89816 | CQ42: x
B43: Imposto de renda | C43: [%] | D43: =-D42/D38 -> 0.26662363 | E43: =-E42/E38 -> 0.41301518 | F43: =-F42/F38 -> 0.37367042 | G43: =-G42/G38 -> 0.46736948 | H43: =-H42/H38 -> -0.77777778 | I43: =-I42/I38 -> 0.72805508 | J43: =-J42/J38 -> 2.0483729 | K43: =-K42/K38 -> -0.41957314 | ... AJ43: =-AJ42/AJ38 -> 0.31298102 | AK43: =AJ43 -> 0.31298102 | AL43: =AK43 -> 0.31298102 | AM43: =AL43 -> 0.31298102 | AN43: =AM43 -> 0.31298102 | AO43: =AN43 -> 0.31298102 | AP43: =AO43 -> 0.31298102 | AQ43: =AP43 -> 0.31298102 | AR43: =AQ43 -> 0.31298102 | ... BW43: =BV43 -> 0.31298102 | BX43: x | BY43: =-BY42/BY38 -> 0.45922998 | BZ43: =-BZ42/BZ38 -> 0.13830679 | CA43: =-CA42/CA38 -> -0.85373391 | CB43: =-CB42/CB38 -> 0.72213247 | CC43: =-CC42/CC38 -> 0.10383831 | CD43: =-CD42/CD38 -> 0.22862913 | CE43: =-CE42/CE38 -> 0.40865362 | CF43: =-CF42/CF38 -> 0.28866031 | ... CP43: =-CP42/CP38 -> 0.31298102 | CQ43: x
B44: Diferido | C44: [BRL 000] | BX44: x | CQ44: x
B45: Corrente | C45: [BRL 000] | BX45: x | CQ45: x
BX46: x | CQ46: x
...

Sheet Build-Up
B7: Valores em R$ (Milhares) | C7: Unidade | D7: 1T17 | E7: 2T17 | F7: 3T17 | G7: 4T17 | H7: 1T18 | I7: 2T18 | J7: 3T18 | K7: 4T18 | L7: 1T19 | M7: 2T19 | N7: 3T19 | O7: 4T19 | P7: 1T20 | Q7: 2T20 | R7: 3T20 | S7: 4T20 | T7: 1T21 | U7: 2T21 | V7: 3T21 | W7: 4T21 | X7: 1T22 | Y7: 2T22 | Z7: 3T22 | AA7: 4T22 | AB7: 1T23 | AC7: 2T23 | AD7: 3T23 | AE7: 4T23 | AF7: 1T24 | AG7: 2T24 | AH7: 3T24 | AI7: 4T24 | AJ7: 1T25 | AK7: 2T25 | AL7: 3T25 | AM7: 4T25 | AN7: 1T26 | AO7: 2T26 | AP7: 3T26 | AQ7: 4T26 | AR7: 1T27 | AS7: 2T27 | AT7: 3T27 | AU7: 4T27 | AV7: 1T28 | AW7: 2T28 | AX7: 3T28 | AY7: 4T28 | AZ7: 1T29 | BA7: 2T29 | BB7: 3T29 | BC7: 4T29 | BD7: 1T30 | BE7: 2T30 | BF7: 3T30 | BG7: 4T30 | BH7: 1T31 | BI7: 2T31 | BJ7: 3T31 | BK7: 4T31 | BL7: 1T32 | BM7: 2T32 | BN7: 3T32 | BO7: 4T32 | BP7: 1T33 | BQ7: 2T33 | BR7: 3T33 | BS7: 4T33 | BT7: 1T34 | BU7: 2T34 | BV7: 3T34 | BW7: 4T34 | BX7: x | BY7: 2017 | BZ7: =BY7+1 -> 2018 | CA7: =BZ7+1 -> 2019 | CB7: =CA7+1 -> 2020 | CC7: =CB7+1 -> 2021 | CD7: =CC7+1 -> 2022 | CE7: =CD7+1 -> 2023 | CF7: =CE7+1 -> 2024 | CG7: =CF7+1 -> 2025 | ... CP7: =CO7+1 -> 2034 | CQ7: x | CR7: CAGR: 17-24 | CS7: CAGR: 19-23 | CT7: CAGR: 22-24 | CU7: CAGR: 23-26 | CV7: CAGR: 24-28 | CW7: CAGR: 25-28
BX8: x | CQ8: x
A9: l | B9: Quebra da Receita Bruta e Líquida | BX9: x | CQ9: x | CR9: =CF35/(1+CF15+CF18) -> 288.66876
BX10: x | CQ10: x
B11: Receita Bruta | C11: [BRL 000] | D11: =Inputs!F344/1000 -> 58.518 | E11: =Inputs!G344/1000 -> 59.783 | F11: =Inputs!H344/1000 -> 67.278 | G11: =Inputs!I344/1000 -> 75.153 | H11: =Inputs!J344/1000 -> 83.716 | I11: =Inputs!K344/1000 -> 92.528 | J11: =Inputs!L344/1000 -> 87.657 | K11: =Inputs!M344/1000 -> 96.578 | ... W11: =Inputs!Y344/1000 -> 130.823 | X11: =Inputs!Z309/1000 -> 141.28999 | Y11: =Inputs!AA309/1000 -> 200.75693 | Z11: =Inputs!AB309/1000 -> 276.42344 | AA11: =Inputs!AC309/1000 -> 266.63214 | AB11: =Inputs!AD309/1000 -> 261.54306 | AC11: =Inputs!AE309/1000 -> 274.60451 | AD11: =Inputs!AF309/1000 -> 293.4205 | AE11: =Inputs!AG309/1000 -> 310.04005 | ... AG11: =Inputs!AI309/1000 -> 227.09262 | AH11: =Inputs!AJ344/1000 -> 432.75508 | AI11: =Inputs!AK344/1000 -> 458.05011 | AJ11: =Inputs!AL344/1000 -> 403.20242 | AK11: =AK20/(1+AK15+AK18) -> 392.24141 | AL11: =AL20/(1+AL15+AL18) -> 408.57771 | AM11: =AM20/(1+AM15+AM18) -> 453.92669 | AN11: =AN20/(1+AN15+AN18) -> 424.32508 | AO11: =AO20/(1+AO15+AO18) -> 426.21414 | AP11: =AP20/(1+AP15+AP18) -> 457.50021 | AQ11: =AQ20/(1+AQ15+AQ18) -> 504.61505 | AR11: =AR20/(1+AR15+AR18) -> 469.38424 | ... BW11: =BW20/(1+BW15+BW18) -> 1025.0819 | BX11: x | BY11: =SUM(D11:G11) -> 260.732 | BZ11: =SUM(H11:K11) -> 360.479 | CA11: =SUM(L11:O11) -> 388.153 | CB11: =SUM(P11:S11) -> 268.803 | CC11: =SUM(T11:W11) -> 472.785 | CD11: =SUM(X11:AA11) -> 885.10249 | CE11: =SUM(AB11:AE11) -> 1139.6081 | CF11: =SUM(AF11:AI11) -> 1356.1719 | CG11: =SUM(AJ11:AM11) -> 1657.9482 | CH11: =SUM(AN11:AQ11) -> 1812.6545 | CI11: =SUM(AR11:AU11) -> 1991.0038 | CJ11: =SUM(AV11:AY11) -> 2175.4388 | CK11: =SUM(AZ11:BC11) -> 2376.9589 | CL11: =SUM(BD11:BG11) -> 2597.1466 | CM11: =SUM(BH11:BK11) -> 2837.7312 | CN11: =SUM(BL11:BO11) -> 3100.6022 | CO11: =SUM(BP11:BS11) -> 3387.8241 | CP11: =SUM(BT11:BW11) -> 3701.6525 | CQ11: x | CR11: =(CF11/BY11)^(1/7)-1 -> 0.26561879 | CS11: =(CE11/CA11)^(1/4)-1 -> 0.30899548 | CT11: =(CF11/CD11)^(1/2)-1 -> 0.23782882 | CU11: =(CH11/CE11)^(1/3)-1 -> 0.16731078 | CV11: =(CJ11/CF11)^(1/4)-1 -> 0.12540291 | CW11: =(CJ11/CG11)^(1/3)-1 -> 0.09477609
B12: a/a % | C12: [%] | H12: =H11/D11-1 -> 0.43060255 | I12: =I11/E11-1 -> 0.54773096 | J12: =J11/F11-1 -> 0.30290734 | K12: =K11/G11-1 -> 0.28508509 | L12: =L11/H11-1 -> 0.088155191 | M12: =M11/I11-1 -> 0.12007176 | N12: =N11/J11-1 -> 0.085070217 | O12: =O11/K11-1 -> 0.017881919 | ... BW12: =BW11/BS11-1 -> 0.09263421 | BX12: x | BZ12: =BZ11/BY11-1 -> 0.38256524 | CA12: =CA11/BZ11-1 -> 0.076770075 | CB12: =CB11/CA11-1 -> -0.30748184 | CC12: =CC11/CB11-1 -> 0.75885314 | CD12: =CD11/CC11-1 -> 0.87210358 | CE12: =CE11/CD11-1 -> 0.28754369 | CF12: =CF11/CE11-1 -> 0.19003355 | CG12: =CG11/CF11-1 -> 0.22252071 | ... CP12: =CP11/CO11-1 -> 0.09263421 | CQ12: x
BX13: x | CQ13: x
B14: Tributos sobre as vendas | D14: -6.178 | E14: -5.694 | F14: -5.811 | G14: -6.139 | H14: -6.872 | I14: -7.462 | J14: -6.975 | K14: -8.066 | L14: -7.455 | M14: -7.941 | N14: -7.564 | O14: -8.348 | P14: -6.136 | Q14: -4.427 | R14: -4.343 | S14: -5.587 | T14: -6.225 | U14: =Inputs!W370/1000 -> -8.837 | V14: =Inputs!X370/1000 -> -10.4 | W14: =Inputs!Y370/1000 -> -9.711 | X14: =Inputs!Z370/1000 -> -10.219 | Y14: =Inputs!AA370/1000 -> -15.45 | Z14: =Inputs!AB370/1000 -> -20.534 | AA14: =Inputs!AC370/1000 -> -18.594 | AB14: =Inputs!AD370/1000 -> -18.887 | ... AG14: =Inputs!AI370/1000 -> -18.617 | AH14: =AH20-AH11+AH17 -> -46.198874 | AI14: =AI20-AI11+AI17 -> -41.653592 | AJ14: =AJ20-AJ11+AJ17 -> -35.886535 | AK14: =AK15*AK$11 -> -32.155859 | AL14: =AL15*AL$11 -> -43.617813 | AM14: =AM15*AM$11 -> -41.278623 | AN14: =AN15*AN$11 -> -37.766531 | AO14: =AO15*AO$11 -> -34.940935 | AP14: =AP15*AP$11 -> -48.840547 | AQ14: =AQ15*AQ$11 -> -45.888057 | AR14: =AR15*AR$11 -> -41.776966 | ... BW14: =BW15*BW$11 -> -93.217623 | BX14: x | BY14: =SUM(D14:G14) -> -23.822 | BZ14: =SUM(H14:K14) -> -29.375 | CA14: =SUM(L14:O14) -> -31.308 | CB14: =SUM(P14:S14) -> -20.493 | CC14: =SUM(T14:W14) -> -35.173 | CD14: =SUM(X14:AA14) -> -64.797 | CE14: =SUM(AB14:AE14) -> -85.332 | CF14: =SUM(AF14:AI14) -> -127.06347 | CG14: =SUM(AJ14:AM14) -> -152.93883 | CH14: =SUM(AN14:AQ14) -> -167.43607 | CI14: =SUM(AR14:AU14) -> -183.87271 | CJ14: =SUM(AV14:AY14) -> -200.90561 | CK14: =SUM(AZ14:BC14) -> -219.51634 | CL14: =SUM(BD14:BG14) -> -239.85107 | CM14: =SUM(BH14:BK14) -> -262.06948 | CN14: =SUM(BL14:BO14) -> -286.34608 | CO14: =SUM(BP14:BS14) -> -312.87152 | CP14: =SUM(BT14:BW14) -> -341.85413 | CQ14: x
B15: % da Receita Bruta | D15: =D14/D$11 -> -0.10557435 | E15: =E14/E$11 -> -0.095244467 | F15: =F14/F$11 -> -0.08637296 | G15: =G14/G$11 -> -0.081686692 | H15: =H14/H$11 -> -0.082087056 | I15: =I14/I$11 -> -0.080645859 | J15: =J14/J$11 -> -0.079571512 | K15: =K14/K$11 -> -0.083517985 | ... AJ15: =AJ14/AJ$11 -> -0.089003768 | AK15: =AG15 -> -0.081979766 | AL15: =AH15 -> -0.10675524 | AM15: =AI15 -> -0.09093676 | AN15: =AJ15 -> -0.089003768 | AO15: =AK15 -> -0.081979766 | AP15: =AL15 -> -0.10675524 | AQ15: =AM15 -> -0.09093676 | AR15: =AN15 -> -0.089003768 | ... BW15: =BS15 -> -0.09093676 | BX15: x | CE15: =CE14/CE11 -> -0.074878371 | CF15: =CF14/CF11 -> -0.093692744 | CG15: =CG14/CG11 -> -0.092245841 | CH15: =CH14/CH11 -> -0.092370649 | CI15: =CI14/CI11 -> -0.092351762 | CJ15: =CJ14/CJ11 -> -0.092351762 | CK15: =CK14/CK11 -> -0.092351762 | CL15: =CL14/CL11 -> -0.092351762 | ... CP15: =CP14/CP11 -> -0.092351762
BX16: x
B17: Cancelamentos | D17: -0.048 | E17: -0.063 | F17: -0.068 | G17: -0.229 | H17: -0.748 | I17: -0.74 | J17: -0.798 | K17: -1.581 | L17: -0.761 | M17: -3.241 | N17: -2.162 | O17: -2.069 | P17: -0.077 | Q17: -2.967 | R17: -2.444 | S17: -0.609 | T17: -0.684 | U17: =Inputs!W371/1000 -> -0.812 | V17: =Inputs!X371/1000 -> -1.456 | W17: =Inputs!Y371/1000 -> -1.519 | X17: =Inputs!Z371/1000 -> -1.783 | Y17: =Inputs!AA371/1000 -> -1.365 | Z17: =Inputs!AB371/1000 -> -1.45 | AA17: =Inputs!AC371/1000 -> -2.213 | AB17: =Inputs!AD371/1000 -> -1.394 | ... AJ17: =Inputs!AL371/1000 -> -1.529 | AK17: =AK18*AK$11 -> -5.5530476 | AL17: =AL18*AL$11 -> -5.7780849 | AM17: =AM18*AM$11 -> -3.2663291 | AN17: =AN18*AN$11 -> -1.6091001 | AO17: =AO18*AO$11 -> -6.0340069 | AP17: =AP18*AP$11 -> -6.4699443 | AQ17: =AQ18*AQ$11 -> -3.6310683 | AR17: =AR18*AR$11 -> -1.7799707 | ... BW17: =BW18*BW$11 -> -7.3762014 | BX17: x | BY17: =SUM(D17:G17) -> -0.408 | BZ17: =SUM(H17:K17) -> -3.867 | CA17: =SUM(L17:O17) -> -8.233 | CB17: =SUM(P17:S17) -> -6.097 | CC17: =SUM(T17:W17) -> -4.471 | CD17: =SUM(X17:AA17) -> -6.811 | CE17: =SUM(AB17:AE17) -> -7.865 | CF17: =SUM(AF17:AI17) -> -13.88 | CG17: =SUM(AJ17:AM17) -> -16.126462 | CH17: =SUM(AN17:AQ17) -> -17.74412 | CI17: =SUM(AR17:AU17) -> -19.475929 | CJ17: =SUM(AV17:AY17) -> -21.280067 | CK17: =SUM(AZ17:BC17) -> -23.251329 | CL17: =SUM(BD17:BG17) -> -25.405197 | CM17: =SUM(BH17:BK17) -> -27.758588 | CN17: =SUM(BL17:BO17) -> -30.329983 | CO17: =SUM(BP17:BS17) -> -33.139577 | CP17: =SUM(BT17:BW17) -> -36.209435 | CQ17: x
B18: % da Receita Bruta | D18: =D17/D$11 -> -0.00082026043 | E18: =E17/E$11 -> -0.0010538113 | F18: =F17/F$11 -> -0.0010107316 | G18: =G17/G$11 -> -0.0030471172 | H18: =H17/H$11 -> -0.0089349706 | I18: =I17/I$11 -> -0.0079975791 | J18: =J17/J$11 -> -0.0091036654 | K18: =K17/K$11 -> -0.016370188 | ... AJ18: =AJ17/AJ$11 -> -0.0037921399 | AK18: =AG18 -> -0.014157219 | AL18: =AH18 -> -0.014141948 | AM18: =AI18 -> -0.0071957193 | AN18: =AJ18 -> -0.0037921399 | AO18: =AK18 -> -0.014157219 | AP18: =AL18 -> -0.014141948 | AQ18: =AM18 -> -0.0071957193 | AR18: =AN18 -> -0.0037921399 | ... BW18: =BS18 -> -0.0071957193 | BX18: x | CE18: =CE17/CE11 -> -0.0069014952 | CF18: =CF17/CF11 -> -0.010234691 | CG18: =CG17/CG11 -> -0.0097267582 | CH18: =CH17/CH11 -> -0.0097890248 | CI18: =CI17/CI11 -> -0.0097819651 | CJ18: =CJ17/CJ11 -> -0.0097819651 | CK18: =CK17/CK11 -> -0.0097819651 | CL18: =CL17/CL11 -> -0.0097819651 | ... CP18: =CP17/CP11 -> -0.0097819651
BX19: x | CQ19: x
B20: Receita Líquida | C20: [BRL 000] | D20: =D11+D14+D17 -> 52.292 | E20: =E11+E14+E17 -> 54.026 | F20: =F11+F14+F17 -> 61.399 | G20: =G11+G14+G17 -> 68.785 | H20: =H11+H14+H17 -> 76.096 | I20: =I11+I14+I17 -> 84.326 | J20: =J11+J14+J17 -> 79.884 | K20: =K11+K14+K17 -> 86.931 | ... AG20: =AG11+AG14+AG17 -> 205.26062 | AH20: =Inputs!AJ314/1000 -> 392.6762 | AI20: =Inputs!AK314/1000 -> 419.69251 | AJ20: =Inputs!AL314/1000 -> 368.84489 | AK20: =AK44*AK47*3/1000 -> 354.5325 | AL20: =AL44*AL47*3/1000 -> 359.18181 | AM20: =AM44*AM47*3/1000 -> 409.38174 | AN20: =AN44*AN47*3/1000 -> 384.94945 | AO20: =AO44*AO47*3/1000 -> 385.23919 | AP20: =AP44*AP47*3/1000 -> 402.18972 | AQ20: =AQ44*AQ47*3/1000 -> 455.09592 | AR20: =AR44*AR47*3/1000 -> 425.82731 | ... BW20: =BW44*BW47*3/1000 -> 924.48804 | BX20: x | BY20: =SUM(D20:G20) -> 236.502 | BZ20: =SUM(H20:K20) -> 327.237 | CA20: =SUM(L20:O20) -> 348.612 | CB20: =SUM(P20:S20) -> 242.213 | CC20: =SUM(T20:W20) -> 433.141 | CD20: =SUM(X20:AA20) -> 813.49449 | CE20: =SUM(AB20:AE20) -> 1046.4111 | CF20: =SUM(AF20:AI20) -> 1234.0604 | CG20: =SUM(AJ20:AM20) -> 1491.9409 | CH20: =SUM(AN20:AQ20) -> 1627.4743 | CI20: =SUM(AR20:AU20) -> 1787.6551 | CJ20: =SUM(AV20:AY20) -> 1953.2532 | CK20: =SUM(AZ20:BC20) -> 2134.1912 | CL20: =SUM(BD20:BG20) -> 2331.8903 | CM20: =SUM(BH20:BK20) -> 2547.9032 | CN20: =SUM(BL20:BO20) -> 2783.9262 | CO20: =SUM(BP20:BS20) -> 3041.813 | CP20: =SUM(BT20:BW20) -> 3323.5889 | CQ20: x | CR20: =(CF20/BY20)^(1/7)-1 -> 0.26619394 | CS20: =(CE20/CA20)^(1/4)-1 -> 0.31625491 | CT20: =(CF20/CD20)^(1/2)-1 -> 0.2316602 | CU20: =(CH20/CE20)^(1/3)-1 -> 0.15860997 | CV20: =(CJ20/CF20)^(1/4)-1 -> 0.12164526 | CW20: =(CJ20/CG20)^(1/3)-1 -> 0.093962163
B21: a/a % | C21: [%] | H21: =H20/D20-1 -> 0.45521303 | I21: =I20/E20-1 -> 0.56084108 | J21: =J20/F20-1 -> 0.30106354 | K21: =K20/G20-1 -> 0.26380752 | L21: =L20/H20-1 -> 0.089150547 | M21: =M20/I20-1 -> 0.096411546 | N21: =N20/J20-1 -> 0.068899905 | O21: =O20/K20-1 -> 0.011008731 | ... BW21: =BW20/BS20-1 -> 0.09263421 | BX21: x | BZ21: =BZ20/BY20-1 -> 0.38365426 | CA21: =CA20/BZ20-1 -> 0.065319631 | CB21: =CB20/CA20-1 -> -0.30520751 | CC21: =CC20/CB20-1 -> 0.78826487 | CD21: =CD20/CC20-1 -> 0.87812858 | CE21: =CE20/CD20-1 -> 0.28631618 | CF21: =CF20/CE20-1 -> 0.17932656 | CG21: =CG20/CF20-1 -> 0.20896911 | ... CP21: =CP20/CO20-1 -> 0.09263421 | CQ21: x
BX22: x | CQ22: x
B23: =Inputs!B315 -> Serviços Industriais | C23: [BRL 000] | X23: =Inputs!Z315/1000 -> 122.98938 | Y23: =Inputs!AA315/1000 -> 153.37301 | Z23: =Inputs!AB315/1000 -> 168.143 | AA23: =Inputs!AC315/1000 -> 175.15283 | AB23: =Inputs!AD315/1000 -> 190.062 | AC23: =Inputs!AE315/1000 -> 198.1976 | AD23: =Inputs!AF315/1000 -> 214.61302 | AE23: =Inputs!AG315/1000 -> 212.85253 | ... AJ23: =Inputs!AL315/1000 -> 197.11955 | AK23: =AK$20*AK25 -> 191.27155 | AL23: =AL$20*AL25 -> 193.77987 | AM23: =AM$20*AM25 -> 220.86292 | AN23: =AN$20*AN25 -> 207.68161 | AO23: =AO$20*AO25 -> 207.83793 | AP23: =AP$20*AP25 -> 216.98279 | AQ23: =AQ$20*AQ25 -> 245.52588 | AR23: =AR$20*AR25 -> 229.73536 | ... BW23: =BW$20*BW25 -> 498.76461 | BX23: x | BY23: =SUM(D23:G23) -> 0 | BZ23: =SUM(H23:K23) -> 0 | CA23: =SUM(L23:O23) -> 0 | CB23: =SUM(P23:S23) -> 0 | CC23: =SUM(T23:W23) -> 0 | CD23: =SUM(X23:AA23) -> 619.65821 | CE23: =SUM(AB23:AE23) -> 815.72515 | CF23: =SUM(AF23:AI23) -> 686.441 | CG23: =SUM(AJ23:AM23) -> 803.0339 | CH23: =SUM(AN23:AQ23) -> 878.02821 | CI23: =SUM(AR23:AU23) -> 964.44636 | CJ23: =SUM(AV23:AY23) -> 1053.7871 | CK23: =SUM(AZ23:BC23) -> 1151.4038 | CL23: =SUM(BD23:BG23) -> 1258.0632 | CM23: =SUM(BH23:BK23) -> 1374.6029 | CN23: =SUM(BL23:BO23) -> 1501.9381 | CO23: =SUM(BP23:BS23) -> 1641.069 | CP23: =SUM(BT23:BW23) -> 1793.0881 | CQ23: x | CT23: =(CF23/CD23)^(1/2)-1 -> 0.052508239 | CU23: =(CH23/CE23)^(1/3)-1 -> 0.02483718 | CV23: =(CJ23/CF23)^(1/4)-1 -> 0.11310828 | CW23: =(CJ23/CG23)^(1/3)-1 -> 0.094812291
B24: a/a % | C24: [%] | AB24: =AB23/X23-1 -> 0.54535298 | AC24: =AC23/Y23-1 -> 0.29225865 | AD24: =AD23/Z23-1 -> 0.27637204 | AE24: =AE23/AA23-1 -> 0.21523889 | AF24: =AF23/AB23-1 -> -0.14510475 | AG24: =AG23/AC23-1 -> -0.27932575 | AH24: =AH23/AD23-1 -> -0.16551298 | AI24: =AI23/AE23-1 -> -0.050844173 | ... BW24: =BW23/BS23-1 -> 0.09263421 | BX24: x | CE24: =CE23/CD23-1 -> 0.31641142 | CF24: =CF23/CE23-1 -> -0.15848983 | CG24: =CG23/CF23-1 -> 0.16985129 | CH24: =CH23/CG23-1 -> 0.093388727 | CI24: =CI23/CH23-1 -> 0.098422971 | CJ24: =CJ23/CI23-1 -> 0.09263421 | CK24: =CK23/CJ23-1 -> 0.09263421 | CL24: =CL23/CK23-1 -> 0.09263421 | ... CP24: =CP23/CO23-1 -> 0.09263421 | CQ24: x
B25: % da Receita Líquida | C25: [%] | AB25: =AB23/AB$20 -> 0.78778238 | AC25: =AC23/AC$20 -> 0.78050674 | AD25: =AD23/AD$20 -> 0.79794696 | AE25: =AE23/AE$20 -> 0.75410613 | AF25: =AF23/AF$20 -> 0.75073824 | AG25: =AG23/AG$20 -> 0.69587584 | AH25: =AH23/AH$20 -> 0.45608005 | AI25: =AI23/AI$20 -> 0.48137674 | AJ25: =AJ23/AJ$20 -> 0.53442397 | AK25: =1-AK29-AK33-AK37 -> 0.53950358 | AL25: =1-AL29-AL33-AL37 -> 0.53950358 | AM25: =1-AM29-AM33-AM37 -> 0.53950358 | AN25: =1-AN29-AN33-AN37 -> 0.53950358 | AO25: =1-AO29-AO33-AO37 -> 0.53950358 | AP25: =1-AP29-AP33-AP37 -> 0.53950358 | AQ25: =1-AQ29-AQ33-AQ37 -> 0.53950358 | AR25: =1-AR29-AR33-AR37 -> 0.53950358 | ... BW25: =1-BW29-BW33-BW37 -> 0.53950358 | BX25: x | CE25: =CE23/CE$20 -> 0.77954556 | CF25: =CF23/CF$20 -> 0.55624586 | CG25: =CG23/CG$20 -> 0.53824778 | CH25: =CH23/CH$20 -> 0.53950358 | CI25: =CI23/CI$20 -> 0.53950358 | CJ25: =CJ23/CJ$20 -> 0.53950358 | CK25: =CK23/CK$20 -> 0.53950358 | CL25: =CL23/CL$20 -> 0.53950358 | ... CP25: =CP23/CP$20 -> 0.53950358 | CQ25: x
BX26: x | CQ26: x
B27: =Inputs!B316 -> Infraestrutura | C27: [BRL 000] | X27: =Inputs!Z316/1000 -> 0.095427 | Y27: =Inputs!AA316/1000 -> 18.902717 | Z27: =Inputs!AB316/1000 -> 73.998 | AA27: =Inputs!AC316/1000 -> 50.129099 | AB27: =Inputs!AD316/1000 -> 33.594 | AC27: =Inputs!AE316/1000 -> 36.303978 | AD27: =Inputs!AF316/1000 -> 34.569031 | AE27: =Inputs!AG316/1000 -> 43.604203 | ... AJ27: =Inputs!AL316/1000 -> 30.477155 | AK27: =AK$20*AK29 -> 35.45325 | AL27: =AL$20*AL29 -> 35.918181 | AM27: =AM$20*AM29 -> 40.938174 | AN27: =AN$20*AN29 -> 38.494945 | AO27: =AO$20*AO29 -> 38.523919 | AP27: =AP$20*AP29 -> 40.218972 | AQ27: =AQ$20*AQ29 -> 45.509592 | AR27: =AR$20*AR29 -> 42.582731 | ... BW27: =BW$20*BW29 -> 92.448804 | BX27: x | BY27: =SUM(D27:G27) -> 0 | BZ27: =SUM(H27:K27) -> 0 | CA27: =SUM(L27:O27) -> 0 | CB27: =SUM(P27:S27) -> 0 | CC27: =SUM(T27:W27) -> 0 | CD27: =SUM(X27:AA27) -> 143.12524 | CE27: =SUM(AB27:AE27) -> 148.07121 | CF27: =SUM(AF27:AI27) -> 157.80389 | CG27: =SUM(AJ27:AM27) -> 142.78676 | CH27: =SUM(AN27:AQ27) -> 162.74743 | CI27: =SUM(AR27:AU27) -> 178.76551 | CJ27: =SUM(AV27:AY27) -> 195.32532 | CK27: =SUM(AZ27:BC27) -> 213.41912 | CL27: =SUM(BD27:BG27) -> 233.18903 | CM27: =SUM(BH27:BK27) -> 254.79032 | CN27: =SUM(BL27:BO27) -> 278.39262 | CO27: =SUM(BP27:BS27) -> 304.1813 | CP27: =SUM(BT27:BW27) -> 332.35889 | CQ27: x | CT27: =(CF27/CD27)^(1/2)-1 -> 0.050027642 | CU27: =(CH27/CE27)^(1/3)-1 -> 0.032003494 | CV27: =(CJ27/CF27)^(1/4)-1 -> 0.054775925 | CW27: =(CJ27/CG27)^(1/3)-1 -> 0.11008661
B28: a/a % | C28: [%] | AB28: =AB27/X27-1 -> 351.03873 | AC28: =AC27/Y27-1 -> 0.9205693 | AD28: =AD27/Z27-1 -> -0.53283831 | AE28: =AE27/AA27-1 -> -0.13016184 | AF28: =AF27/AB27-1 -> -0.093913986 | AG28: =AG27/AC27-1 -> -0.088717095 | AH28: =AH27/AD27-1 -> 0.11818432 | AI28: =AI27/AE27-1 -> 0.27572776 | ... BW28: =BW27/BS27-1 -> 0.09263421 | BX28: x | CE28: =CE27/CD27-1 -> 0.034556931 | CF28: =CF27/CE27-1 -> 0.065729701 | CG28: =CG27/CF27-1 -> -0.095163237 | CH28: =CH27/CG27-1 -> 0.13979355 | CI28: =CI27/CH27-1 -> 0.098422971 | CJ28: =CJ27/CI27-1 -> 0.09263421 | CK28: =CK27/CJ27-1 -> 0.09263421 | CL28: =CL27/CK27-1 -> 0.09263421 | ... CP28: =CP27/CO27-1 -> 0.09263421 | CQ28: x
B29: % da Receita Líquida | C29: [%] | AB29: =AB27/AB$20 -> 0.13924278 | AC29: =AC27/AC$20 -> 0.14296591 | AD29: =AD27/AD$20 -> 0.12853019 | AE29: =AE27/AE$20 -> 0.15448347 | AF29: =AF27/AF$20 -> 0.14064085 | AG29: =AG27/AG$20 -> 0.16117653 | AH29: =AH27/AH$20 -> 0.098438734 | AI29: =AI27/AI$20 -> 0.13254249 | AJ29: =AJ27/AJ$20 -> 0.082628648 | AK29: 0.1 | AL29: 0.1 | AM29: 0.1 | AN29: 0.1 | AO29: 0.1 | AP29: 0.1 | AQ29: 0.1 | AR29: 0.1 | AS29: 0.1 | AT29: 0.1 | AU29: 0.1 | AV29: 0.1 | AW29: 0.1 | AX29: 0.1 | AY29: 0.1 | AZ29: 0.1 | BA29: 0.1 | BB29: 0.1 | BC29: 0.1 | BD29: 0.1 | BE29: 0.1 | BF29: 0.1 | BG29: 0.1 | BH29: 0.1 | BI29: 0.1 | BJ29: 0.1 | BK29: 0.1 | BL29: 0.1 | BM29: 0.1 | BN29: 0.1 | BO29: 0.1 | BP29: 0.1 | BQ29: 0.1 | BR29: 0.1 | BS29: 0.1 | BT29: 0.1 | BU29: 0.1 | BV29: 0.1 | BW29: 0.1 | BX29: x | CE29: =CE27/CE$20 -> 0.14150386 | CF29: =CF27/CF$20 -> 0.12787371 | CG29: =CG27/CG$20 -> 0.09570537 | CH29: =CH27/CH$20 -> 0.1 | CI29: =CI27/CI$20 -> 0.1 | CJ29: =CJ27/CJ$20 -> 0.1 | CK29: =CK27/CK$20 -> 0.1 | CL29: =CL27/CL$20 -> 0.1 | ... CP29: =CP27/CP$20 -> 0.1 | CQ29: x
BX30: x | CQ30: x
B31: =Inputs!B317 -> Engenharia de Integridade e Inspeção | C31: [BRL 000] | X31: =Inputs!Z317/1000 -> 6.203014 | Y31: =Inputs!AA317/1000 -> 11.666569 | Z31: =Inputs!AB317/1000 -> 12.298 | AA31: =Inputs!AC317/1000 -> 20.543072 | AB31: =Inputs!AD317/1000 -> 17.606 | AC31: =Inputs!AE317/1000 -> 19.432719 | AD31: =Inputs!AF317/1000 -> 19.774975 | AE31: =Inputs!AG317/1000 -> 25.800374 | ... AJ31: =Inputs!AL317/1000 -> 43.321189 | AK31: =AK$20*AK33 -> 33.680588 | AL31: =AL$20*AL33 -> 34.122272 | AM31: =AM$20*AM33 -> 38.891266 | AN31: =AN$20*AN33 -> 36.570198 | AO31: =AO$20*AO33 -> 36.597723 | AP31: =AP$20*AP33 -> 38.208023 | AQ31: =AQ$20*AQ33 -> 43.234113 | AR31: =AR$20*AR33 -> 40.453594 | ... BW31: =BW$20*BW33 -> 87.826364 | BX31: x | BY31: =SUM(D31:G31) -> 0 | BZ31: =SUM(H31:K31) -> 0 | CA31: =SUM(L31:O31) -> 0 | CB31: =SUM(P31:S31) -> 0 | CC31: =SUM(T31:W31) -> 0 | CD31: =SUM(X31:AA31) -> 50.710655 | CE31: =SUM(AB31:AE31) -> 82.614068 | CF31: =SUM(AF31:AI31) -> 131.14673 | CG31: =SUM(AJ31:AM31) -> 150.01531 | CH31: =SUM(AN31:AQ31) -> 154.61006 | CI31: =SUM(AR31:AU31) -> 169.82724 | CJ31: =SUM(AV31:AY31) -> 185.55905 | CK31: =SUM(AZ31:BC31) -> 202.74817 | CL31: =SUM(BD31:BG31) -> 221.52958 | CM31: =SUM(BH31:BK31) -> 242.0508 | CN31: =SUM(BL31:BO31) -> 264.47299 | CO31: =SUM(BP31:BS31) -> 288.97223 | CP31: =SUM(BT31:BW31) -> 315.74095 | CQ31: x | CT31: =(CF31/CD31)^(1/2)-1 -> 0.60815952 | CU31: =(CH31/CE31)^(1/3)-1 -> 0.23233253 | CV31: =(CJ31/CF31)^(1/4)-1 -> 0.090639361 | CW31: =(CJ31/CG31)^(1/3)-1 -> 0.073450893
B32: a/a % | C32: [%] | AB32: =AB31/X31-1 -> 1.8382976 | AC32: =AC31/Y31-1 -> 0.66567557 | AD32: =AD31/Z31-1 -> 0.60798301 | AE32: =AE31/AA31-1 -> 0.25591605 | AF32: =AF31/AB31-1 -> 0.33525379 | AG32: =AG31/AC31-1 -> 0.50989333 | AH32: =AH31/AD31-1 -> 1.0962178 | AI32: =AI31/AE31-1 -> 0.42805168 | ... BW32: =BW31/BS31-1 -> 0.09263421 | BX32: x | CE32: =CE31/CD31-1 -> 0.62912642 | CF32: =CF31/CE31-1 -> 0.58746247 | CG32: =CG31/CF31-1 -> 0.14387383 | CH32: =CH31/CG31-1 -> 0.030628491 | CI32: =CI31/CH31-1 -> 0.098422971 | CJ32: =CJ31/CI31-1 -> 0.09263421 | CK32: =CK31/CJ31-1 -> 0.09263421 | CL32: =CL31/CK31-1 -> 0.09263421 | ... CP32: =CP31/CO31-1 -> 0.09263421 | CQ32: x
B33: % da Receita Líquida | C33: [%] | AB33: =AB31/AB$20 -> 0.07297459 | AC33: =AC31/AC$20 -> 0.076526498 | AD33: =AD31/AD$20 -> 0.073524807 | AE33: =AE31/AE$20 -> 0.091407044 | AF33: =AF31/AF$20 -> 0.10861876 | AG33: =AG31/AG$20 -> 0.14294672 | AH33: =AH31/AH$20 -> 0.10556447 | AI33: =AI31/AI$20 -> 0.087788716 | AJ33: =AJ31/AJ$20 -> 0.11745097 | AK33: 0.095 | AL33: 0.095 | AM33: 0.095 | AN33: 0.095 | AO33: 0.095 | AP33: 0.095 | AQ33: 0.095 | AR33: 0.095 | AS33: 0.095 | AT33: 0.095 | AU33: 0.095 | AV33: 0.095 | AW33: 0.095 | AX33: 0.095 | AY33: 0.095 | AZ33: 0.095 | BA33: 0.095 | BB33: 0.095 | BC33: 0.095 | BD33: 0.095 | BE33: 0.095 | BF33: 0.095 | BG33: 0.095 | BH33: 0.095 | BI33: 0.095 | BJ33: 0.095 | BK33: 0.095 | BL33: 0.095 | BM33: 0.095 | BN33: 0.095 | BO33: 0.095 | BP33: 0.095 | BQ33: 0.095 | BR33: 0.095 | BS33: 0.095 | BT33: 0.095 | BU33: 0.095 | BV33: 0.095 | BW33: 0.095 | BX33: x | CE33: =CE31/CE$20 -> 0.078949913 | CF33: =CF31/CF$20 -> 0.10627254 | CG33: =CG31/CG$20 -> 0.10055044 | CH33: =CH31/CH$20 -> 0.095 | CI33: =CI31/CI$20 -> 0.095 | CJ33: =CJ31/CJ$20 -> 0.095 | CK33: =CK31/CK$20 -> 0.095 | CL33: =CL31/CL$20 -> 0.095 | ... CP33: =CP31/CP$20 -> 0.095 | CQ33: x
BX34: x | CQ34: x
B35: Montagem | C35: [BRL 000] | AH35: =Inputs!AJ318/1000 -> 133.47722 | AI35: =Inputs!AK318/1000 -> 125.19094 | AJ35: =Inputs!AL318/1000 -> 97.926996 | AK35: =AK$20*AK37 -> 94.127108 | AL35: =AL$20*AL37 -> 95.361483 | AM35: =AM$20*AM37 -> 108.68939 | AN35: =AN$20*AN37 -> 102.2027 | AO35: =AO$20*AO37 -> 102.27962 | AP35: =AP$20*AP37 -> 106.77993 | AQ35: =AQ$20*AQ37 -> 120.82634 | AR35: =AR$20*AR37 -> 113.05562 | ... BW35: =BW$20*BW37 -> 245.44826 | BX35: x | BY35: =SUM(D35:G35) -> 0 | BZ35: =SUM(H35:K35) -> 0 | CA35: =SUM(L35:O35) -> 0 | CB35: =SUM(P35:S35) -> 0 | CC35: =SUM(T35:W35) -> 0 | CD35: =SUM(X35:AA35) -> 0 | CE35: =SUM(AB35:AE35) -> 0 | CF35: =SUM(AF35:AI35) -> 258.66816 | CG35: =SUM(AJ35:AM35) -> 396.10497 | CH35: =SUM(AN35:AQ35) -> 432.08859 | CI35: =SUM(AR35:AU35) -> 474.61603 | CJ35: =SUM(AV35:AY35) -> 518.58171 | CK35: =SUM(AZ35:BC35) -> 566.62012 | CL35: =SUM(BD35:BG35) -> 619.10853 | CM35: =SUM(BH35:BK35) -> 676.45916 | CN35: =SUM(BL35:BO35) -> 739.12242 | CO35: =SUM(BP35:BS35) -> 807.59044 | CP35: =SUM(BT35:BW35) -> 882.40094 | CQ35: x | CV35: =(CJ35/CF35)^(1/4)-1 -> 0.18992217 | CW35: =(CJ35/CG35)^(1/3)-1 -> 0.093962163
B36: a/a % | C36: [%] | BX36: x | CG36: =CG35/CF35-1 -> 0.53132482 | CH36: =CH35/CG35-1 -> 0.090843637 | CI36: =CI35/CH35-1 -> 0.098422971 | CJ36: =CJ35/CI35-1 -> 0.09263421 | CK36: =CK35/CJ35-1 -> 0.09263421 | CL36: =CL35/CK35-1 -> 0.09263421 | CM36: =CM35/CL35-1 -> 0.09263421 | CN36: =CN35/CM35-1 -> 0.09263421 | ... CP36: =CP35/CO35-1 -> 0.09263421 | CQ36: x
B37: % da Receita Líquida | C37: [%] | AH37: =AH35/AH$20 -> 0.33991675 | AI37: =AI35/AI$20 -> 0.29829205 | AJ37: =AJ35/AJ$20 -> 0.26549642 | AK37: =AJ37 -> 0.26549642 | AL37: =AK37 -> 0.26549642 | AM37: =AL37 -> 0.26549642 | AN37: =AM37 -> 0.26549642 | AO37: =AN37 -> 0.26549642 | AP37: =AO37 -> 0.26549642 | AQ37: =AP37 -> 0.26549642 | AR37: =AQ37 -> 0.26549642 | ... BW37: =BV37 -> 0.26549642 | BX37: x | CE37: =CE35/CE$20 -> 0 | CF37: =CF35/CF$20 -> 0.20960737 | CG37: =CG35/CG$20 -> 0.26549642 | CH37: =CH35/CH$20 -> 0.26549642 | CI37: =CI35/CI$20 -> 0.26549642 | CJ37: =CJ35/CJ$20 -> 0.26549642 | CK37: =CK35/CK$20 -> 0.26549642 | CL37: =CL35/CL$20 -> 0.26549642 | ... CP37: =CP35/CP$20 -> 0.26549642 | CQ37: x
BX38: x | CQ38: x
A39: l | B39: Dados Operacionais | BX39: x | CQ39: x
BX40: x | CQ40: x
B41: =Inputs!B278 -> Quantidade total de colaboradores (final de trimestre) | D41: =Inputs!F278 -> 2023 | E41: =Inputs!G278 -> 2046 | F41: =Inputs!H278 -> 2758 | G41: =Inputs!I278 -> 2598 | H41: =Inputs!J278 -> 3202 | I41: =Inputs!K278 -> 3316 | J41: =Inputs!L278 -> 3177 | K41: =Inputs!M278 -> 3111 | ... AJ41: =Inputs!AL278 -> 6967 | AK41: =6602 -> 6602 | AL41: =AK41*(1+AL42) -> 6701.03 | AM41: =AL41*(1+AM42) -> 6801.5454 | AN41: =AM41*(1+AN42) -> 6903.5686 | AO41: =AN41*(1+AO42) -> 7007.1222 | AP41: =AO41*(1+AP42) -> 7112.229 | AQ41: =AP41*(1+AQ42) -> 7183.3513 | AR41: =AQ41*(1+AR42) -> 7255.1848 | AS41: =AR41*(1+AS42) -> 7327.7366 | ... BW41: =BV41*(1+BW42) -> 9876.6819 | BX41: x | BY41: =G41 -> 2598 | BZ41: =K41 -> 3111 | CA41: =O41 -> 2676 | CB41: =S41 -> 2199 | CC41: =W41 -> 3200 | CD41: =AA41 -> 5256 | CE41: =AE41 -> 5350 | CF41: =AI41 -> 6994 | CG41: =AM41 -> 6801.5454 | CH41: =AQ41 -> 7183.3513 | CI41: =AU41 -> 7475.0242 | CJ41: =AY41 -> 7778.5401 | CK41: =BC41 -> 8094.38 | CL41: =BG41 -> 8423.0443 | CM41: =BK41 -> 8765.0537 | CN41: =BO41 -> 9120.95 | CO41: =BS41 -> 9491.2972 | CP41: =BW41 -> 9876.6819 | CQ41: x
B42: a/a % | H42: =H41/D41-1 -> 0.58279782 | I42: =I41/E41-1 -> 0.62072336 | J42: =J41/F41-1 -> 0.15192168 | K42: =K41/G41-1 -> 0.19745958 | L42: =L41/H41-1 -> 0.064334791 | M42: =M41/I41-1 -> -0.10283474 | N42: =N41/J41-1 -> -0.084985836 | O42: =O41/K41-1 -> -0.13982642 | ... AJ42: =AJ41/AF41-1 -> 0.57838695 | AK42: 0.01 | AL42: 0.015 | AM42: 0.015 | AN42: 0.015 | AO42: 0.015 | AP42: 0.015 | AQ42: 0.01 | AR42: 0.01 | AS42: 0.01 | AT42: 0.01 | AU42: 0.01 | AV42: 0.01 | AW42: 0.01 | AX42: 0.01 | AY42: 0.01 | AZ42: 0.01 | BA42: 0.01 | BB42: 0.01 | BC42: 0.01 | BD42: 0.01 | BE42: 0.01 | BF42: 0.01 | BG42: 0.01 | BH42: 0.01 | BI42: 0.01 | BJ42: 0.01 | BK42: 0.01 | BL42: 0.01 | BM42: 0.01 | BN42: 0.01 | BO42: 0.01 | BP42: 0.01 | BQ42: 0.01 | BR42: 0.01 | BS42: 0.01 | BT42: 0.01 | BU42: 0.01 | BV42: 0.01 | BW42: 0.01 | BX42: x | BZ42: =BZ41/BY41-1 -> 0.19745958 | CA42: =CA41/BZ41-1 -> -0.13982642 | CB42: =CB41/CA41-1 -> -0.17825112 | CC42: =CC41/CB41-1 -> 0.45520691 | CD42: =CD41/CC41-1 -> 0.6425 | CE42: =CE41/CD41-1 -> 0.017884323 | CF42: =CF41/CE41-1 -> 0.30728972 | CG42: =CG41/CF41-1 -> -0.027517093 | ... CP42: =CP41/CO41-1 -> 0.04060401 | CQ42: x
BX43: x | CQ43: x
B44: =Inputs!B279 -> Quantidade total de colaboradores (média mensal do trimestre) | D44: =Inputs!F279 -> 2023 | E44: =Inputs!G279 -> 2034.5 | F44: =Inputs!H279 -> 2402 | G44: =Inputs!I279 -> 2678 | H44: =Inputs!J279 -> 2900 | I44: =Inputs!K279 -> 3259 | J44: =Inputs!L279 -> 3246.5 | K44: =Inputs!M279 -> 3144 | ... X44: =Inputs!Z279 -> 3558.3333 | Y44: =Inputs!AA280 -> 3995.5 | Z44: =Inputs!AB280 -> 4345.5 | AA44: =Inputs!AC280 -> 4907 | AB44: =Inputs!AD279 -> 5745.6667 | AC44: =Inputs!AE279 -> 5776.6667 | AD44: =Inputs!AF279 -> 5832.3333 | AE44: =Inputs!AG279 -> 5567.3333 | AF44: =Inputs!AH279 -> 4281.3333 | AG44: =Inputs!AI279 -> 4632.6667 | AH44: =Inputs!AJ279 -> 7276 | AI44: =Inputs!AK279 -> 7302 | AJ44: =Inputs!AL279 -> 6927 | AK44: =6753 -> 6753 | AL44: =(AL41+AK41)/2 -> 6651.515 | AM44: =(AM41+AL41)/2 -> 6751.2877 | AN44: =(AN41+AM41)/2 -> 6852.557 | AO44: =(AO41+AN41)/2 -> 6955.3454 | AP44: =(AP41+AO41)/2 -> 7059.6756 | AQ44: =(AQ41+AP41)/2 -> 7147.7901 | AR44: =(AR41+AQ41)/2 -> 7219.268 | AS44: =(AS41+AR41)/2 -> 7291.4607 | ... BW44: =(BW41+BV41)/2 -> 9827.7874 | BX44: x | BY44: =AVERAGE(G44,D44) -> 2350.5 | BZ44: =AVERAGE(H44:K44) -> 3137.375 | CA44: =AVERAGE(L44:O44) -> 3045.875 | CB44: =AVERAGE(P44:S44) -> 2044.0833 | CC44: =AVERAGE(T44:W44) -> 2962.1667 | CD44: =AVERAGE(X44:AA44) -> 4201.5833 | CE44: =AVERAGE(AB44:AE44) -> 5730.5 | CF44: =AI44 -> 7302 | CG44: =AM44 -> 6751.2877 | CH44: =AQ44 -> 7147.7901 | CI44: =AU44 -> 7438.0191 | CJ44: =AY44 -> 7740.0325 | CK44: =BC44 -> 8054.3088 | CL44: =BG44 -> 8381.3461 | CM44: =BK44 -> 8721.6623 | CN44: =BO44 -> 9075.7968 | CO44: =BS44 -> 9444.3105 | CP44: =BW44 -> 9827.7874 | CQ44: x
B45: a/a % | H45: =H44/D44-1 -> 0.43351458 | I45: =I44/E44-1 -> 0.60186778 | J45: =J44/F44-1 -> 0.35158202 | K45: =K44/G44-1 -> 0.17401046 | L45: =L44/H44-1 -> 0.12396552 | M45: =M44/I44-1 -> -0.020711875 | N45: =N44/J44-1 -> -0.09410134 | O45: =O44/K44-1 -> -0.11211832 | ... BW45: =BW44/BS44-1 -> 0.04060401 | BX45: x | BZ45: =BZ44/BY44-1 -> 0.3347692 | CA45: =CA44/BZ44-1 -> -0.029164509 | CB45: =CB44/CA44-1 -> -0.32890111 | CC45: =CC44/CB44-1 -> 0.44914183 | CD45: =CD44/CC44-1 -> 0.41841557 | CE45: =CE44/CD44-1 -> 0.3638906 | CF45: =CF44/CE44-1 -> 0.27423436 | CG45: =CG44/CF44-1 -> -0.075419375 | ... CP45: =CP44/CO44-1 -> 0.04060401 | CQ45: x
BX46: x | CQ46: x
...

Sheet Valuation
B7: Valores em R$ (Milhares) | C7: Unidade | BA7: =Modelo!BY7 -> 2017 | BB7: =Modelo!BZ7 -> 2018 | BC7: =Modelo!CA7 -> 2019 | BD7: =Modelo!CB7 -> 2020 | BE7: =Modelo!CC7 -> 2021 | BF7: =Modelo!CD7 -> 2022 | BG7: =Modelo!CE7 -> 2023 | BH7: =Modelo!CF7 -> 2024 | ... BR7: =Modelo!CP7 -> 2034 | BS7: Perpetuidade | BU7: =Modelo!CQ7 -> x
BU8: =Modelo!CQ8 -> x
A9: l | B9: Fluxos de Caixa Livre | BU9: =Modelo!CQ9 -> x
BU10: =Modelo!CQ10 -> x
BH11: 45657 | BI11: 46022 | BJ11: 46387 | BK11: 46752 | BL11: 47118 | BM11: 47483 | BN11: 47848 | BO11: 48213 | BP11: 48579 | BQ11: 48944 | BR11: 49309 | BU11: =Modelo!CQ11 -> x
B12: FCO | C12: [BRL 000] | BH12: =+BH13+BH14+BH15+BH16 -> 145.95633 | BI12: =+BI13+BI14+BI15+BI16 -> 248.54217 | BJ12: =+BJ13+BJ14+BJ15+BJ16 -> 260.61273 | BK12: =+BK13+BK14+BK15+BK16 -> 268.10472 | BL12: =+BL13+BL14+BL15+BL16 -> 287.34494 | BM12: =+BM13+BM14+BM15+BM16 -> 307.88508 | BN12: =+BN13+BN14+BN15+BN16 -> 332.2228 | BO12: =+BO13+BO14+BO15+BO16 -> 359.22093 | ... BR12: =+BR13+BR14+BR15+BR16 -> 455.7975 | BU12: =Modelo!CQ12 -> x
B13: (+) EBITDA | BH13: =Modelo!CF52 -> 160.61833 | BI13: =Modelo!CG52 -> 193.94655 | BJ13: =Modelo!CH52 -> 250.90167 | BK13: =Modelo!CI52 -> 284.04885 | BL13: =Modelo!CJ52 -> 316.80139 | BM13: =Modelo!CK52 -> 343.34172 | BN13: =Modelo!CL52 -> 372.73552 | BO13: =Modelo!CM52 -> 405.13546 | ... BR13: =Modelo!CP52 -> 517.8069 | BU13: =Modelo!CQ13 -> x
B14: (-) Imposto | BH14: =Modelo!CF42 -> -17.147 | BI14: =Modelo!CG42 -> -18.632059 | BJ14: =Modelo!CH42 -> -39.281412 | BK14: =Modelo!CI42 -> -51.337677 | BL14: =Modelo!CJ42 -> -63.582446 | BM14: =Modelo!CK42 -> -72.523293 | BN14: =Modelo!CL42 -> -81.767304 | BO14: =Modelo!CM42 -> -91.923493 | ... BR14: =Modelo!CP42 -> -129.89816 | BU14: =Modelo!CQ14 -> x
B15: (-) ∆ Capital de Giro | BH15: =Modelo!CF140 -> -20.891 | BI15: =Modelo!CG140 -> 27.112751 | BJ15: =Modelo!CH140 -> -8.2527546 | BK15: =Modelo!CI140 -> -15.568925 | BL15: =Modelo!CJ140 -> -16.684434 | BM15: =Modelo!CK140 -> -18.229983 | BN15: =Modelo!CL140 -> -19.918703 | BO15: =Modelo!CM140 -> -21.763856 | ... BR15: =Modelo!CP140 -> -28.389663 | BU15: =Modelo!CQ15 -> x
B16: (+) Receitas Financeiras | BH16: =Modelo!CF35 -> 23.376 | BI16: =Modelo!CG35 -> 46.114931 | BJ16: =Modelo!CH35 -> 57.245224 | BK16: =Modelo!CI35 -> 50.962464 | BL16: =Modelo!CJ35 -> 50.810426 | BM16: =Modelo!CK35 -> 55.296637 | BN16: =Modelo!CL35 -> 61.173289 | BO16: =Modelo!CM35 -> 67.772816 | ... BR16: =Modelo!CP35 -> 96.278428 | BU16: =Modelo!CQ16 -> x
B17: FCI | BH17: =+BH18 -> -93.599 | BI17: =+BI18 -> -85.623622 | BJ17: =+BJ18 -> -97.648457 | BK17: =+BK18 -> -107.25931 | BL17: =+BL18 -> -117.19519 | BM17: =+BM18 -> -128.05147 | BN17: =+BN18 -> -139.91342 | BO17: =+BO18 -> -152.87419 | ... BR17: =+BR18 -> -166.17945 | BU17: =Modelo!CQ17 -> x
B18: (-) CAPEX | BH18: =Modelo!CF144+Modelo!CF145 -> -93.599 | BI18: =Modelo!CG144+Modelo!CG145 -> -85.623622 | BJ18: =Modelo!CH144+Modelo!CH145 -> -97.648457 | BK18: =Modelo!CI144+Modelo!CI145 -> -107.25931 | BL18: =Modelo!CJ144+Modelo!CJ145 -> -117.19519 | BM18: =Modelo!CK144+Modelo!CK145 -> -128.05147 | BN18: =Modelo!CL144+Modelo!CL145 -> -139.91342 | BO18: =Modelo!CM144+Modelo!CM145 -> -152.87419 | ... BR18: =Modelo!CP144+Modelo!CP145 -> -166.17945 | BU18: =Modelo!CQ18 -> x
B19: FCF | BH19: =+BH20+BH21+BH22 -> 39.855 | BI19: =+BI20+BI21+BI22 -> 47.954302 | BJ19: =+BJ20+BJ21+BJ22 -> -107.30025 | BK19: =+BK20+BK21+BK22 -> -91.925404 | BL19: =+BL20+BL21+BL22 -> -81.405772 | BM19: =+BM20+BM21+BM22 -> -78.978164 | BN19: =+BN20+BN21+BN22 -> -78.978164 | BO19: =+BO20+BO21+BO22 -> -78.978164 | ... BR19: =+BR20+BR21+BR22 -> -78.978164 | BU19: =Modelo!CQ19 -> x
